{
  "task_id": 414,
  "code": "def candidate(sequence, target):\n    \"\"\"\n    Checks if a given value exists in a sequence.\n\n    Args:\n        sequence (iterable): The sequence to search in.\n        target: The value to search for.\n\n    Returns:\n        bool: True if the target is found in the sequence, False otherwise.\n    \"\"\"\n    # Check if both inputs are iterable\n    if not hasattr(sequence, '__getitem__'):\n        raise TypeError(\"Sequence must be a list or any other iterable\")\n\n    try:\n        return target in sequence\n    except Exception as e:\n        print(f\"Error: {e}\")",
  "explanation": "Explanation\nThe original code attempts to check if a target value exists in a given sequence. However, it has several issues including incorrect type checking and exception handling. The error message indicates that the assertion `candidate([1,4,5],[1,4,5]) == True` is failing.\n\nCode",
  "num_iterations": 6,
  "error_msg": "Traceback (most recent call last):\n  File \"/home/runner/sandbox/temp_code.py\", line 23, in <module>\n    assert candidate([1,4,5],[1,4,5]) == True\n           ^^^^^^^^^^^^^^^^^^^^^^^^^^^^^^^^^^\nAssertionError\n\n",
  "success": false
}